<?xml version="1.0"?>

<robot name="rover" xmlns:xacro="http://wiki.ros.org/xacro">
  <xacro:macro name="gripper" params="parent">
  
    <joint name="06_arm_base_fingers_R_joint" type="revolute">
      <limit lower="-3.14000" upper="3.14000" effort="1000" velocity="100.00000"/>
      <origin rpy="0.00000 0.00000 0.00000" xyz="0.00000 0.00000 -0.02500"/>
      <parent link="${parent}"/>
      <child link="arm_base_fingers_link_R"/>
      <axis xyz="0.00000 0.00000 1.00000"/>
    </joint>
    <joint name="07_arm_finger_right_joint" type="prismatic">
      <limit lower="0.00000" upper="0.11000" effort="1000" velocity="100.00000"/>
      <origin rpy="0.00000 0.00000 0.00000" xyz="-0.00000 -0.37500 -0.22500"/>
      <parent link="arm_base_fingers_link_R"/>
      <child link="arm_finger_right_link"/>
      <axis xyz="0.00000 1.00000 0.00000"/>
    </joint>
    <joint name="08_arm_finger_left_joint" type="prismatic">
      <limit lower="-0.11000" upper="0.00000" effort="1000" velocity="100.00000"/>
      <origin rpy="0.00000 0.00000 0.00000" xyz="-0.00000 0.37500 -0.22500"/>
      <parent link="arm_base_fingers_link_R"/>
      <child link="arm_finger_left_link"/>
      <axis xyz="0.00000 1.00000 0.00000"/>
    </joint>
    <link name="arm_base_fingers_link_R">
      <collision name="arm_base_fingers_collision">
        <origin rpy="0.00000 0.00000 0.00000" xyz="-0.00000 0.00000 -0.00000"/>
        <geometry>
          <box size="0.40000 0.80000 0.05000"/>
        </geometry>
      </collision>
      <inertial>
        <inertia ixx="0.02677" ixy="0.00000" ixz="0.00000" iyy="0.00677" iyz="0.00000" izz="0.03333"/>
        <origin rpy="0.00000 0.00000 0.00000" xyz="-0.00000 0.00000 -0.00000"/>
        <mass value="0.50000"/>
      </inertial>
      <visual name="arm_base_fingers">
        <origin rpy="0.00000 0.00000 0.00000" xyz="-0.00000 0.00000 0.00000"/>
        <material name="Material.gray"/>
        <geometry>
          <box size="0.40000 0.80000 0.05000"/>
        </geometry>
      </visual>
    </link>
    <link name="arm_finger_left_link">
      <collision name="arm_finger_left_collision">
        <origin rpy="0.00000 0.00000 0.00000" xyz="-0.00000 -0.00000 0.00000"/>
        <geometry>
          <box size="0.40000 0.05000 0.40000"/>
        </geometry>
      </collision>
      <inertial>
        <inertia ixx="0.00406" ixy="0.00000" ixz="0.00000" iyy="0.00800" iyz="0.00000" izz="0.00406"/>
        <origin rpy="0.00000 0.00000 0.00000" xyz="-0.00000 0.00000 -0.00000"/>
        <mass value="0.30000"/>
      </inertial>
      <visual name="arm_finger_left">
        <origin rpy="0.00000 0.00000 0.00000" xyz="0.00000 0.00000 -0.00000"/>
        <material name="Material.gray"/>
        <geometry>
          <box size="0.40000 0.05000 0.40000"/>
        </geometry>
      </visual>
    </link>
    <link name="arm_finger_right_link">
      <collision name="arm_finger_right_collision">
        <origin rpy="0.00000 0.00000 0.00000" xyz="-0.00000 0.00000 0.00000"/>
        <geometry>
          <box size="0.40000 0.05000 0.40000"/>
        </geometry>
      </collision>
      <inertial>
        <inertia ixx="0.00406" ixy="0.00000" ixz="0.00000" iyy="0.00800" iyz="0.00000" izz="0.00406"/>
        <origin rpy="0.00000 0.00000 0.00000" xyz="-0.00000 0.00000 -0.00000"/>
        <mass value="0.30000"/>
      </inertial>
      <visual name="arm_finger_right">
        <origin rpy="0.00000 0.00000 0.00000" xyz="0.00000 -0.00000 -0.00000"/>
        <material name="Material.gray"/>
        <geometry>
          <box size="0.40000 0.05000 0.40000"/>
        </geometry>
      </visual>
    </link>

  </xacro:macro>
</robot>